Workbook

Sheet Data
A1: Mã hồ sơ / ClaimID | B1: Tên bệnh nhân / PatientName | C1: Có bảo hiểm / HasInsurance | D1: Tên bác sĩ / DoctorName | E1: Khoa / Department | F1: Trong bảo hiểm / CoveredByInsurance | G1: Số tiền yêu cầu thanh toán VND / ClaimAmountVND | H1: Tên dịch vụ / ProcedureName | I1: Mã ICD10 / DiagnosisCode | J1: Chẩn đoán / DiagnosisName | K1: Tuổi / PatientAge | L1: Giới tính / PatientGender | M1: Thu nhập / PatientIncome | N1: Tình trạng hôn nhân / PatientMaritalStatus | O1: Tình trạng việc làm / PatientEmploymentStatus | P1: Ngày hồ sơ / ClaimDate | Q1: Loại hồ sơ / ClaimType | R1: Phương thức nộp / ClaimSubmissionMethod | S1: Địa điểm provider / ProviderLocation | T1: Trạng thái hồ sơ gốc / SourceClaimStatus | U1: ClaimLegitimacy nguồn / SourceClaimLegitimacy | V1: Cluster nguồn / SourceCluster | W1: SourcePatientID | X1: SourceProviderID | Y1: SourceProcedureCode | Z1: SourceDiagnosisCode | AA1: Điểm suy luận có BH / InsuranceInferenceScore | AB1: Điểm suy luận covered / CoverageInferenceScore | AC1: Logic tạo dữ liệu / DataDerivationNote | AD1: Formula has_insurance_status | AE1: Formula covered_status | AF1: Formula review_flag
A2: 4d76c7f7-d36a-4139-b451-a9a4ad10d7d5 | B2: BN-00001 / Patient 19CF2638 | C2: Có | D2: BS. Trần An | E2: Chấn thương chỉnh hình / Orthopedics | F2: Không | G2: 7820520 | H2: Đo mật độ xương / Bone density scan | I2: M81.0 | J2: Loãng xương / Osteoporosis | K2: 96 | L2: F | M2: 57595.11 | N2: Single | O2: Employed | P2: 45481 | Q2: Inpatient | R2: Paper | S2: New Alishaview | T2: Pending | U2: Legitimate | V2: 3 | W2: 19cf2638-3ec0-4ed9-9995-d9ba4553813a | X2: a3d0cc80-dffe-40ff-a302-23c8ffeedb36 | Y2: iO013 | Z2: Ta150 | AA2: 0.86 | AB2: 0.09 | AC2: Derived from original claim row: HasInsurance uses PatientEmploymentStatus/ClaimType/SubmissionMethod/Income/Age; CoveredByInsurance uses SourceClaimStatus + procedure sensitivity/high-cost + claim type + doctor pattern. | AD2: =IF(OR(C2="Có",C2="Yes"),"yes",IF(OR(C2="Không",C2="No"),"no","unknown")) | AE2: =IF(OR(F2="Có",F2="Yes"),"covered",IF(OR(F2="Không",F2="No"),"out_of_insurance","unknown")) | AF2: =IF(AND(AD2="yes",AE2="out_of_insurance"),"REVIEW","")
A3: e35193b4-3609-492b-866a-98de19317e9c | B3: BN-00002 / Patient 5C4BB6C5 | C3: Có | D3: BS. Nguyễn Minh | E3: Tim mạch / Cardiology | F3: Không | G3: 5453860 | H3: CRP định lượng / CRP | I3: R79.8 | J3: Bất thường xét nghiệm máu / Abnormal blood chemistry | K3: 95 | L3: M | M3: 140772.72 | N3: Widowed | O3: Employed | P3: 45481 | Q3: Inpatient | R3: Online | S3: East Curtis | T3: Denied | U3: Legitimate | V3: 2 | W3: 5c4bb6c5-4dd3-4a86-85fa-f36c0d8debff | X3: a9f25acf-92b8-45e2-9cef-87bd07d0a591 | Y3: jR349 | Z3: Fo766 | AA3: 0.78 | AB3: 0.02 | AC3: Derived from original claim row: HasInsurance uses PatientEmploymentStatus/ClaimType/SubmissionMethod/Income/Age; CoveredByInsurance uses SourceClaimStatus + procedure sensitivity/high-cost + claim type + doctor pattern. | AD3: =IF(OR(C3="Có",C3="Yes"),"yes",IF(OR(C3="Không",C3="No"),"no","unknown")) | AE3: =IF(OR(F3="Có",F3="Yes"),"covered",IF(OR(F3="Không",F3="No"),"out_of_insurance","unknown")) | AF3: =IF(AND(AD3="yes",AE3="out_of_insurance"),"REVIEW","")
A4: 1f3fa373-25ed-4ff4-b6c7-38dcb2fb297f | B4: BN-00003 / Patient 777866E0 | C4: Có | D4: BS. Trương Khải | E4: Tim mạch / Cardiology | F4: Không | G4: 8229860 | H4: Đông máu PT/aPTT / Coagulation test | I4: I24.9 | J4: Bệnh tim thiếu máu cục bộ cấp / Acute ischemic heart disease | K4: 10 | L4: M | M4: 69803.19 | N4: Married | O4: Student | P4: 45481 | Q4: Emergency | R4: Online | S4: Lake Jennifer | T4: Pending | U4: Legitimate | V4: 3 | W4: 777866e0-4d10-45a8-a7b4-dbdaa26d5a81 | X4: 951b1e08-9948-4956-80e5-9277f16bd290 | Y4: uU479 | Z4: AX876 | AA4: 0.63 | AB4: 0.28 | AC4: Derived from original claim row: HasInsurance uses PatientEmploymentStatus/ClaimType/SubmissionMethod/Income/Age; CoveredByInsurance uses SourceClaimStatus + procedure sensitivity/high-cost + claim type + doctor pattern. | AD4: =IF(OR(C4="Có",C4="Yes"),"yes",IF(OR(C4="Không",C4="No"),"no","unknown")) | AE4: =IF(OR(F4="Có",F4="Yes"),"covered",IF(OR(F4="Không",F4="No"),"out_of_insurance","unknown")) | AF4: =IF(AND(AD4="yes",AE4="out_of_insurance"),"REVIEW","")
A5: af6a68f4-8319-47b1-a28b-77de01572851 | B5: BN-00004 / Patient 9D7C53EE | C5: Có | D5: BS. Nguyễn Minh | E5: Tim mạch / Cardiology | F5: Không | G5: 9519160 | H5: Đông máu PT/aPTT / Coagulation test | I5: I24.9 | J5: Bệnh tim thiếu máu cục bộ cấp / Acute ischemic heart disease | K5: 59 | L5: F | M5: 135530.12 | N5: Married | O5: Employed | P5: 45481 | Q5: Routine | R5: Phone | S5: Martinstad | T5: Pending | U5: Legitimate | V5: 2 | W5: 9d7c53ee-eb1a-4f07-9e3a-e86cf82e9f0f | X5: de9e193a-f9a1-4d63-9345-aefe75694628 | Y5: Xs264 | Z5: SQ441 | AA5: 0.66 | AB5: 0.02 | AC5: Derived from original claim row: HasInsurance uses PatientEmploymentStatus/ClaimType/SubmissionMethod/Income/Age; CoveredByInsurance uses SourceClaimStatus + procedure sensitivity/high-cost + claim type + doctor pattern. | AD5: =IF(OR(C5="Có",C5="Yes"),"yes",IF(OR(C5="Không",C5="No"),"no","unknown")) | AE5: =IF(OR(F5="Có",F5="Yes"),"covered",IF(OR(F5="Không",F5="No"),"out_of_insurance","unknown")) | AF5: =IF(AND(AD5="yes",AE5="out_of_insurance"),"REVIEW","")
A6: 417fe944-79d2-4610-81c4-a2d496f29ee4 | B6: BN-00005 / Patient DB14B0CA | C6: Có | D6: BS. Lưu Quang | E6: Thần kinh / Neurology | F6: Có | G6: 3226150 | H6: Khám chuyên khoa thần kinh / Neurology consultation | I6: R51 | J6: Đau đầu / Headache | K6: 36 | L6: F | M6: 36995.52 | N6: Divorced | O6: Unemployed | P6: 45481 | Q6: Inpatient | R6: Phone | S6: Thomasfurt | T6: Approved | U6: Legitimate | V6: 1 | W6: db14b0ca-ac2a-4e83-b085-947ea32e7587 | X6: 5c7d7045-71b6-4c15-937c-43e4cfe65bf4 | Y6: PV476 | Z6: FK970 | AA6: 0.69 | AB6: 0.88 | AC6: Derived from original claim row: HasInsurance uses PatientEmploymentStatus/ClaimType/SubmissionMethod/Income/Age; CoveredByInsurance uses SourceClaimStatus + procedure sensitivity/high-cost + claim type + doctor pattern. | AD6: =IF(OR(C6="Có",C6="Yes"),"yes",IF(OR(C6="Không",C6="No"),"no","unknown")) | AE6: =IF(OR(F6="Có",F6="Yes"),"covered",IF(OR(F6="Không",F6="No"),"out_of_insurance","unknown")) | AF6: =IF(AND(AD6="yes",AE6="out_of_insurance"),"REVIEW","")
A7: 41c69c3f-7b63-435c-841f-97633264a347 | B7: BN-00006 / Patient 9CABA0E6 | C7: Không | D7: BS. Hoàng Phúc | E7: Tim mạch / Cardiology | F7: Không | G7: 3476560 | H7: Troponin I định lượng / Troponin I | I7: R07.9 | J7: Đau ngực nghi hội chứng mạch vành / Chest pain, ACS rule-out | K7: 26 | L7: F | M7: 96819.09 | N7: Divorced | O7: Retired | P7: 45480 | Q7: Outpatient | R7: Paper | S7: North Michael | T7: Denied | U7: Legitimate | V7: 0 | W7: 9caba0e6-334d-4132-9330-1c1adaa82d11 | X7: 11ff25ad-29c9-493b-a356-cb0c6a8f41a6 | Y7: Am159 | Z7: ZE958 | AA7: 0.7 | AB7: 0.05 | AC7: Derived from original claim row: HasInsurance uses PatientEmploymentStatus/ClaimType/SubmissionMethod/Income/Age; CoveredByInsurance uses SourceClaimStatus + procedure sensitivity/high-cost + claim type + doctor pattern. | AD7: =IF(OR(C7="Có",C7="Yes"),"yes",IF(OR(C7="Không",C7="No"),"no","unknown")) | AE7: =IF(OR(F7="Có",F7="Yes"),"covered",IF(OR(F7="Không",F7="No"),"out_of_insurance","unknown")) | AF7: =IF(AND(AD7="yes",AE7="out_of_insurance"),"REVIEW","")
A8: 80a92d69-9d51-476c-8d1d-0ea35a7081a9 | B8: BN-00007 / Patient C4DAF0C4 | C8: Có | D8: BS. Phạm Khoa | E8: Thần kinh / Neurology | F8: Không | G8: 6468550 | H8: CT sọ não / Brain CT | I8: R51 | J8: Đau đầu chưa rõ nguyên nhân / Headache unspecified | K8: 3 | L8: M | M8: 117271.04 | N8: Married | O8: Employed | P8: 45480 | Q8: Emergency | R8: Paper | S8: West Paul | T8: Denied | U8: Legitimate | V8: 2 | W8: c4daf0c4-8d67-4aba-97db-442a948db4d3 | X8: 19d62078-bb03-4473-8815-5f814c12b5c8 | Y8: vm240 | Z8: hg131 | AA8: 0.77 | AB8: 0.02 | AC8: Derived from original claim row: HasInsurance uses PatientEmploymentStatus/ClaimType/SubmissionMethod/Income/Age; CoveredByInsurance uses SourceClaimStatus + procedure sensitivity/high-cost + claim type + doctor pattern. | AD8: =IF(OR(C8="Có",C8="Yes"),"yes",IF(OR(C8="Không",C8="No"),"no","unknown")) | AE8: =IF(OR(F8="Có",F8="Yes"),"covered",IF(OR(F8="Không",F8="No"),"out_of_insurance","unknown")) | AF8: =IF(AND(AD8="yes",AE8="out_of_insurance"),"REVIEW","")
A9: 31c804c9-110c-4c26-bf38-2638b9e29526 | B9: BN-00008 / Patient 71D7C4AC | C9: Có | D9: BS. Huỳnh Mai | E9: Nhi / Pediatrics | F9: Không | G9: 350000 | H9: HbA1c | I9: E11.9 | J9: Đái tháo đường type 2 / Type 2 diabetes mellitus | K9: 99 | L9: M | M9: 125318.21 | N9: Widowed | O9: Employed | P9: 45480 | Q9: Inpatient | R9: Paper | S9: Ambermouth | T9: Denied | U9: Legitimate | V9: 2 | W9: 71d7c4ac-c608-4392-8f71-83ce85d00595 | X9: c1bfab96-0df6-4a49-96e1-236bd3c6a7b5 | Y9: eD733 | Z9: Xa559 | AA9: 0.74 | AB9: 0.06 | AC9: Derived from original claim row: HasInsurance uses PatientEmploymentStatus/ClaimType/SubmissionMethod/Income/Age; CoveredByInsurance uses SourceClaimStatus + procedure sensitivity/high-cost + claim type + doctor pattern. | AD9: =IF(OR(C9="Có",C9="Yes"),"yes",IF(OR(C9="Không",C9="No"),"no","unknown")) | AE9: =IF(OR(F9="Có",F9="Yes"),"covered",IF(OR(F9="Không",F9="No"),"out_of_insurance","unknown")) | AF9: =IF(AND(AD9="yes",AE9="out_of_insurance"),"REVIEW","")
A10: 25d801f8-d141-4131-9f1f-0c63360b4302 | B10: BN-00009 / Patient 919F254E | C10: Có | D10: BS. Phạm Khoa | E10: Thần kinh / Neurology | F10: Không | G10: 4661710 | H10: MRI não / Brain MRI | I10: G44.1 | J10: Hội chứng đau đầu mạch máu / Vascular headache | K10: 57 | L10: F | M10: 24263.98 | N10: Widowed | O10: Employed | P10: 45480 | Q10: Inpatient | R10: Paper | S10: Larsonville | T10: Pending | U10: Legitimate | V10: 1 | W10: 919f254e-a7eb-41da-8f14-b2ee11aad6da | X10: 8d1a5376-5ea6-42e6-beec-2c1313a30a49 | Y10: uq058 | Z10: Sj663 | AA10: 0.85 | AB10: 0.02 | AC10: Derived from original claim row: HasInsurance uses PatientEmploymentStatus/ClaimType/SubmissionMethod/Income/Age; CoveredByInsurance uses SourceClaimStatus + procedure sensitivity/high-cost + claim type + doctor pattern. | AD10: =IF(OR(C10="Có",C10="Yes"),"yes",IF(OR(C10="Không",C10="No"),"no","unknown")) | AE10: =IF(OR(F10="Có",F10="Yes"),"covered",IF(OR(F10="Không",F10="No"),"out_of_insurance","unknown")) | AF10: =IF(AND(AD10="yes",AE10="out_of_insurance"),"REVIEW","")
A11: 8b5172a0-9aab-439a-9e3f-d0af5f2a1b6b | B11: BN-00010 / Patient 6D707925 | C11: Không | D11: BS. Đỗ Hạnh | E11: Nhi / Pediatrics | F11: Không | G11: 9638640 | H11: CRP định lượng / CRP | I11: J18.9 | J11: Nghi viêm phổi / Suspected pneumonia | K11: 91 | L11: M | M11: 78191.1 | N11: Widowed | O11: Unemployed | P11: 45480 | Q11: Outpatient | R11: Phone | S11: South Jessicabury | T11: Approved | U11: Legitimate | V11: 3 | W11: 6d707925-803e-42b8-af6e-e77d9f45dd8a | X11: ed55392c-f9e3-469c-9367-00df827b1cf6 | Y11: Gw549 | Z11: Qu671 | AA11: 0.63 | AB11: 0.05 | AC11: Derived from original claim row: HasInsurance uses PatientEmploymentStatus/ClaimType/SubmissionMethod/Income/Age; CoveredByInsurance uses SourceClaimStatus + procedure sensitivity/high-cost + claim type + doctor pattern. | AD11: =IF(OR(C11="Có",C11="Yes"),"yes",IF(OR(C11="Không",C11="No"),"no","unknown")) | AE11: =IF(OR(F11="Có",F11="Yes"),"covered",IF(OR(F11="Không",F11="No"),"out_of_insurance","unknown")) | AF11: =IF(AND(AD11="yes",AE11="out_of_insurance"),"REVIEW","")
A12: 8280ceb3-5e5e-422b-b292-4c200e770e55 | B12: BN-00011 / Patient 5F67A286 | C12: Có | D12: BS. Bùi Hà | E12: Khám tổng quát / General Practice | F12: Chưa rõ | G12: 4808400 | H12: Glucose máu / Blood glucose | I12: R73.9 | J12: Tăng glucose máu / Hyperglycemia | K12: 23 | L12: M | M12: 137214.94 | N12: Married | O12: Student | P12: 45480 | Q12: Outpatient | R12: Online | S12: Timothyshire | T12: Pending | U12: Legitimate | V12: 2 | W12: 5f67a286-cb4c-44c7-9a2a-6eb4b0ae426f | X12: 94c39b96-e407-4daa-a15b-b1cfd56bec90 | Y12: jX265 | Z12: hi217 | AA12: 0.48 | AB12: 0.26 | AC12: Derived from original claim row: HasInsurance uses PatientEmploymentStatus/ClaimType/SubmissionMethod/Income/Age; CoveredByInsurance uses SourceClaimStatus + procedure sensitivity/high-cost + claim type + doctor pattern. | AD12: =IF(OR(C12="Có",C12="Yes"),"yes",IF(OR(C12="Không",C12="No"),"no","unknown")) | AE12: =IF(OR(F12="Có",F12="Yes"),"covered",IF(OR(F12="Không",F12="No"),"out_of_insurance","unknown")) | AF12: =IF(AND(AD12="yes",AE12="out_of_insurance"),"REVIEW","")
A13: 10f62863-4e13-4ad8-8345-775f25b72134 | B13: BN-00012 / Patient 811515B3 | C13: Có | D13: BS. Hà Nam | E13: Chấn thương chỉnh hình / Orthopedics | F13: Chưa rõ | G13: 7549440 | H13: CT cột sống thắt lưng / Lumbar spine CT | I13: M54.5 | J13: Đau thắt lưng / Low back pain | K13: 24 | L13: F | M13: 123904.58 | N13: Single | O13: Unemployed | P13: 45480 | Q13: Outpatient | R13: Online | S13: Mirandaland | T13: Pending | U13: Legitimate | V13: 2 | W13: 811515b3-858c-493a-9e30-0f4cf6d2ed2d | X13: 1bf63333-eed0-404c-afe4-39fc3135728d | Y13: ND467 | Z13: EC314 | AA13: 0.48 | AB13: 0.16 | AC13: Derived from original claim row: HasInsurance uses PatientEmploymentStatus/ClaimType/SubmissionMethod/Income/Age; CoveredByInsurance uses SourceClaimStatus + procedure sensitivity/high-cost + claim type + doctor pattern. | AD13: =IF(OR(C13="Có",C13="Yes"),"yes",IF(OR(C13="Không",C13="No"),"no","unknown")) | AE13: =IF(OR(F13="Có",F13="Yes"),"covered",IF(OR(F13="Không",F13="No"),"out_of_insurance","unknown")) | AF13: =IF(AND(AD13="yes",AE13="out_of_insurance"),"REVIEW","")
... A27: 2082ed1f-7813-45b2-a9dc-500f448030a7 | B27: BN-00026 / Patient 9D8DC859 | C27: Không | D27: BS. Hoàng Phúc | E27: Tim mạch / Cardiology | F27: Không | G27: 7368100 | H27: Đông máu PT/aPTT / Coagulation test | I27: I24.9 | J27: Bệnh tim thiếu máu cục bộ cấp / Acute ischemic heart disease | K27: 77 | L27: F | M27: 23246.22 | N27: Widowed | O27: Student | P27: 45477 | Q27: Routine | R27: Paper | S27: West Ryan | T27: Denied | U27: Legitimate | V27: 1 | W27: 9d8dc859-7907-40e2-b557-64a023b25e1b | X27: 9791fb7b-4214-4f50-9935-f570536ab28b | Y27: UZ482 | Z27: oa422 | AA27: 0.57 | AB27: 0.05 | AC27: Derived from original claim row: HasInsurance uses PatientEmploymentStatus/ClaimType/SubmissionMethod/Income/Age; CoveredByInsurance uses SourceClaimStatus + procedure sensitivity/high-cost + claim type + doctor pattern. | AD27: =IF(OR(C27="Có",C27="Yes"),"yes",IF(OR(C27="Không",C27="No"),"no","unknown")) | AE27: =IF(OR(F27="Có",F27="Yes"),"covered",IF(OR(F27="Không",F27="No"),"out_of_insurance","unknown")) | AF27: =IF(AND(AD27="yes",AE27="out_of_insurance"),"REVIEW","")
A28: 3a3387e2-33dc-4cce-ab5e-6100792ee5e1 | B28: BN-00027 / Patient 4548BADE | C28: Có | D28: BS. Hà Nam | E28: Chấn thương chỉnh hình / Orthopedics | F28: Không | G28: 3871420 | H28: CT cột sống thắt lưng / Lumbar spine CT | J28: Thiếu ICD/context rõ / Missing clear ICD/context | K28: 74 | L28: M | M28: 80354.63 | N28: Divorced | O28: Unemployed | P28: 45477 | Q28: Inpatient | R28: Phone | S28: Kimton | T28: Denied | U28: Legitimate | V28: 3 | W28: 4548bade-b3e3-4657-a445-8744ab81acb0 | X28: 8903c76d-3f84-47c6-a8bc-10a97263e045 | Y28: KR330 | Z28: YQ337 | AA28: 0.6 | AB28: 0.02 | AC28: Derived from original claim row: HasInsurance uses PatientEmploymentStatus/ClaimType/SubmissionMethod/Income/Age; CoveredByInsurance uses SourceClaimStatus + procedure sensitivity/high-cost + claim type + doctor pattern. | AD28: =IF(OR(C28="Có",C28="Yes"),"yes",IF(OR(C28="Không",C28="No"),"no","unknown")) | AE28: =IF(OR(F28="Có",F28="Yes"),"covered",IF(OR(F28="Không",F28="No"),"out_of_insurance","unknown")) | AF28: =IF(AND(AD28="yes",AE28="out_of_insurance"),"REVIEW","")
A29: 74232dc0-6102-4141-a091-523670ba223f | B29: BN-00028 / Patient 0D40B2A2 | C29: Có | D29: BS. Huỳnh Mai | E29: Nhi / Pediatrics | F29: Có | G29: 6045120 | H29: CRP định lượng / CRP | I29: J18.9 | J29: Nghi viêm phổi / Suspected pneumonia | K29: 17 | L29: F | M29: 23792.19 | N29: Single | O29: Employed | P29: 45476 | Q29: Emergency | R29: Phone | S29: Ryanport | T29: Pending | U29: Legitimate | V29: 1 | W29: 0d40b2a2-9e12-49b3-81a7-7eac635ba6df | X29: 3fdca2a5-b49b-4566-9074-4ffbe0d9fd98 | Y29: Ps882 | Z29: PJ904 | AA29: 0.85 | AB29: 0.38 | AC29: Derived from original claim row: HasInsurance uses PatientEmploymentStatus/ClaimType/SubmissionMethod/Income/Age; CoveredByInsurance uses SourceClaimStatus + procedure sensitivity/high-cost + claim type + doctor pattern. | AD29: =IF(OR(C29="Có",C29="Yes"),"yes",IF(OR(C29="Không",C29="No"),"no","unknown")) | AE29: =IF(OR(F29="Có",F29="Yes"),"covered",IF(OR(F29="Không",F29="No"),"out_of_insurance","unknown")) | AF29: =IF(AND(AD29="yes",AE29="out_of_insurance"),"REVIEW","")
A30: 76bf4dbb-0ba0-43d9-a57d-6ef2b8b6ecb2 | B30: BN-00029 / Patient 4DB169BD | C30: Có | D30: BS. Trần An | E30: Chấn thương chỉnh hình / Orthopedics | F30: Không | G30: 6758760 | H30: Đo mật độ xương / Bone density scan | I30: M81.0 | J30: Loãng xương / Osteoporosis | K30: 65 | L30: M | M30: 109264.56 | N30: Widowed | O30: Unemployed | P30: 45476 | Q30: Outpatient | R30: Online | S30: Michaelberg | T30: Pending | U30: Legitimate | V30: 0 | W30: 4db169bd-5011-41f4-a541-d75205e1f416 | X30: af8dddd2-84e2-44e8-a7ed-52b4e66ec0f2 | Y30: Rp360 | Z30: OV896 | AA30: 0.61 | AB30: 0.03 | AC30: Derived from original claim row: HasInsurance uses PatientEmploymentStatus/ClaimType/SubmissionMethod/Income/Age; CoveredByInsurance uses SourceClaimStatus + procedure sensitivity/high-cost + claim type + doctor pattern. | AD30: =IF(OR(C30="Có",C30="Yes"),"yes",IF(OR(C30="Không",C30="No"),"no","unknown")) | AE30: =IF(OR(F30="Có",F30="Yes"),"covered",IF(OR(F30="Không",F30="No"),"out_of_insurance","unknown")) | AF30: =IF(AND(AD30="yes",AE30="out_of_insurance"),"REVIEW","")
A31: 6f795a62-0499-4587-80d0-2f4ea285c946 | B31: BN-00030 / Patient DA04979F | C31: Có | D31: BS. Võ Huy | E31: Chấn thương chỉnh hình / Orthopedics | F31: Có | G31: 7430710 | H31: MRI khớp gối / Knee MRI | I31: M25.5 | J31: Đau khớp gối / Knee pain | K31: 23 | L31: M | M31: 128019.92 | N31: Married | O31: Employed | P31: 45476 | Q31: Outpatient | R31: Paper | S31: Molinahaven | T31: Approved | U31: Legitimate | V31: 2 | W31: da04979f-8887-415e-a9bd-95a5678260ce | X31: 1a5be5c8-0505-4138-b91d-b108241f851c | Y31: kY698 | Z31: zp790 | AA31: 0.72 | AB31: 0.6 | AC31: Derived from original claim row: HasInsurance uses PatientEmploymentStatus/ClaimType/SubmissionMethod/Income/Age; CoveredByInsurance uses SourceClaimStatus + procedure sensitivity/high-cost + claim type + doctor pattern. | AD31: =IF(OR(C31="Có",C31="Yes"),"yes",IF(OR(C31="Không",C31="No"),"no","unknown")) | AE31: =IF(OR(F31="Có",F31="Yes"),"covered",IF(OR(F31="Không",F31="No"),"out_of_insurance","unknown")) | AF31: =IF(AND(AD31="yes",AE31="out_of_insurance"),"REVIEW","")
A32: 9a08463a-7088-46d8-b6d2-cfeaad233f49 | B32: BN-00031 / Patient B171B654 | C32: Có | D32: BS. Đỗ Hạnh | E32: Nhi / Pediatrics | F32: Có | G32: 4384880 | H32: Khám nhi / Pediatric consultation | I32: J06.9 | J32: Viêm hô hấp trên cấp / Acute upper respiratory infection | K32: 5 | L32: M | M32: 104381.93 | N32: Divorced | O32: Student | P32: 45476 | Q32: Outpatient | R32: Online | S32: Port Trevor | T32: Approved | U32: Legitimate | V32: 0 | W32: b171b654-a175-4232-a6ec-a70a804d8bed | X32: 26814c12-8c23-42f9-9c98-94695a7f7ce1 | Y32: yW675 | Z32: vq560 | AA32: 0.62 | AB32: 0.82 | AC32: Derived from original claim row: HasInsurance uses PatientEmploymentStatus/ClaimType/SubmissionMethod/Income/Age; CoveredByInsurance uses SourceClaimStatus + procedure sensitivity/high-cost + claim type + doctor pattern. | AD32: =IF(OR(C32="Có",C32="Yes"),"yes",IF(OR(C32="Không",C32="No"),"no","unknown")) | AE32: =IF(OR(F32="Có",F32="Yes"),"covered",IF(OR(F32="Không",F32="No"),"out_of_insurance","unknown")) | AF32: =IF(AND(AD32="yes",AE32="out_of_insurance"),"REVIEW","")
A33: 060714aa-6270-4dda-9c55-5119378ea5ef | B33: BN-00032 / Patient 6354E321 | C33: Có | D33: BS. Lâm Sơn | E33: Khám tổng quát / General Practice | F33: Không | G33: 8872330 | H33: CRP định lượng / CRP | I33: R79.8 | J33: Bất thường xét nghiệm máu / Abnormal blood chemistry | K33: 88 | L33: M | M33: 98794.25 | N33: Single | O33: Unemployed | P33: 45476 | Q33: Inpatient | R33: Paper | S33: West Andrea | T33: Approved | U33: Legitimate | V33: 0 | W33: 6354e321-a478-4234-9957-706effa06dfa | X33: bcd7a8e2-e93e-4dad-97b6-9f20026fda8a | Y33: ae399 | Z33: MU447 | AA33: 0.7 | AB33: 0.66 | AC33: Derived from original claim row: HasInsurance uses PatientEmploymentStatus/ClaimType/SubmissionMethod/Income/Age; CoveredByInsurance uses SourceClaimStatus + procedure sensitivity/high-cost + claim type + doctor pattern. | AD33: =IF(OR(C33="Có",C33="Yes"),"yes",IF(OR(C33="Không",C33="No"),"no","unknown")) | AE33: =IF(OR(F33="Có",F33="Yes"),"covered",IF(OR(F33="Không",F33="No"),"out_of_insurance","unknown")) | AF33: =IF(AND(AD33="yes",AE33="out_of_insurance"),"REVIEW","")
A34: 60bab648-d33f-4885-9a2a-b05f92f5196f | B34: BN-00033 / Patient 4513605A | C34: Có | D34: BS. Võ Huy | E34: Chấn thương chỉnh hình / Orthopedics | F34: Không | G34: 1200000 | H34: CT cột sống thắt lưng / Lumbar spine CT | I34: M54.5 | J34: Đau thắt lưng / Low back pain | K34: 56 | L34: M | M34: 61948.88 | N34: Married | O34: Student | P34: 45475 | Q34: Emergency | R34: Phone | S34: North Kyle | T34: Pending | U34: Legitimate | V34: 3 | W34: 4513605a-3c23-49b9-abea-479a72169ca8 | X34: 5fcfab50-4bd3-4bbc-8bdc-42394eecb032 | Y34: SY139 | Z34: fq674 | AA34: 0.59 | AB34: 0.28 | AC34: Derived from original claim row: HasInsurance uses PatientEmploymentStatus/ClaimType/SubmissionMethod/Income/Age; CoveredByInsurance uses SourceClaimStatus + procedure sensitivity/high-cost + claim type + doctor pattern. | AD34: =IF(OR(C34="Có",C34="Yes"),"yes",IF(OR(C34="Không",C34="No"),"no","unknown")) | AE34: =IF(OR(F34="Có",F34="Yes"),"covered",IF(OR(F34="Không",F34="No"),"out_of_insurance","unknown")) | AF34: =IF(AND(AD34="yes",AE34="out_of_insurance"),"REVIEW","")
A35: 6089b08a-dd39-4cba-9ba3-fe4ccc9326b0 | B35: BN-00034 / Patient 350C1B2C | C35: Có | D35: BS. Hoàng Phúc | E35: Tim mạch / Cardiology | F35: Không | G35: 4030450 | H35: Đông máu PT/aPTT / Coagulation test | I35: I24.9 | J35: Bệnh tim thiếu máu cục bộ cấp / Acute ischemic heart disease | K35: 64 | L35: F | M35: 48508.39 | N35: Widowed | O35: Retired | P35: 45475 | Q35: Emergency | R35: Phone | S35: Lake Ronald | T35: Denied | U35: Legitimate | V35: 1 | W35: 350c1b2c-dce5-4c0f-8dd0-98638624d22d | X35: 29424123-1a99-4c70-a4e0-e50562aebf35 | Y35: rn473 | Z35: Wa731 | AA35: 0.77 | AB35: 0.12 | AC35: Derived from original claim row: HasInsurance uses PatientEmploymentStatus/ClaimType/SubmissionMethod/Income/Age; CoveredByInsurance uses SourceClaimStatus + procedure sensitivity/high-cost + claim type + doctor pattern. | AD35: =IF(OR(C35="Có",C35="Yes"),"yes",IF(OR(C35="Không",C35="No"),"no","unknown")) | AE35: =IF(OR(F35="Có",F35="Yes"),"covered",IF(OR(F35="Không",F35="No"),"out_of_insurance","unknown")) | AF35: =IF(AND(AD35="yes",AE35="out_of_insurance"),"REVIEW","")
A36: 1d62a811-7da1-4c9d-8b0f-5c155699e993 | B36: BN-00035 / Patient BA8579FB | C36: Có | D36: BS. Huỳnh Mai | E36: Nhi / Pediatrics | F36: Không | G36: 7511590 | H36: CRP định lượng / CRP | I36: J18.9 | J36: Nghi viêm phổi / Suspected pneumonia | K36: 52 | L36: M | M36: 83932.78 | N36: Single | O36: Student | P36: 45475 | Q36: Outpatient | R36: Online | S36: Hortonshire | T36: Denied | U36: Legitimate | V36: 3 | W36: ba8579fb-0750-4603-a938-10db06efee50 | X36: 503979af-a5d8-468b-a88c-786b9f4b126f | Y36: Ec911 | Z36: RN098 | AA36: 0.52 | AB36: 0.02 | AC36: Derived from original claim row: HasInsurance uses PatientEmploymentStatus/ClaimType/SubmissionMethod/Income/Age; CoveredByInsurance uses SourceClaimStatus + procedure sensitivity/high-cost + claim type + doctor pattern. | AD36: =IF(OR(C36="Có",C36="Yes"),"yes",IF(OR(C36="Không",C36="No"),"no","unknown")) | AE36: =IF(OR(F36="Có",F36="Yes"),"covered",IF(OR(F36="Không",F36="No"),"out_of_insurance","unknown")) | AF36: =IF(AND(AD36="yes",AE36="out_of_insurance"),"REVIEW","")
A37: 70089c16-6f54-40bc-b401-4f275c93afe9 | B37: BN-00036 / Patient D88B3B68 | C37: Có | D37: BS. Trương Khải | E37: Tim mạch / Cardiology | F37: Chưa rõ | G37: 4298890 | H37: Siêu âm tim / Echocardiography | I37: I50.9 | J37: Suy tim / Heart failure | K37: 26 | L37: F | M37: 26794.93 | N37: Divorced | O37: Retired | P37: 45474 | Q37: Outpatient | R37: Paper | S37: Maysview | T37: Pending | U37: Legitimate | V37: 1 | W37: d88b3b68-edaa-4eeb-bc09-035a98e3404c | X37: c1d5795e-0e32-4f98-86f5-4d3e9e24da8d | Y37: zU515 | Z37: kV404 | AA37: 0.78 | AB37: 0.28 | AC37: Derived from original claim row: HasInsurance uses PatientEmploymentStatus/ClaimType/SubmissionMethod/Income/Age; CoveredByInsurance uses SourceClaimStatus + procedure sensitivity/high-cost + claim type + doctor pattern. | AD37: =IF(OR(C37="Có",C37="Yes"),"yes",IF(OR(C37="Không",C37="No"),"no","unknown")) | AE37: =IF(OR(F37="Có",F37="Yes"),"covered",IF(OR(F37="Không",F37="No"),"out_of_insurance","unknown")) | AF37: =IF(AND(AD37="yes",AE37="out_of_insurance"),"REVIEW","")
A38: 90da07cb-33bd-434f-a93b-a1404cf90339 | B38: BN-00037 / Patient 5E6D3AB0 | C38: Có | D38: BS. Nguyễn Minh | E38: Tim mạch / Cardiology | F38: Không | G38: 8319180 | H38: Siêu âm tim / Echocardiography | I38: I50.9 | J38: Suy tim / Heart failure | K38: 87 | L38: F | M38: 73669.12 | N38: Divorced | O38: Retired | P38: 45474 | Q38: Inpatient | R38: Paper | S38: Mcintoshstad | T38: Denied | U38: Legitimate | V38: 3 | W38: 5e6d3ab0-4bc1-455a-9663-4ee46eb979ef | X38: 4bdf658b-fab3-4ecb-ae6c-2610110fccf3 | Y38: gd395 | Z38: yp250 | AA38: 0.82 | AB38: 0.02 | AC38: Derived from original claim row: HasInsurance uses PatientEmploymentStatus/ClaimType/SubmissionMethod/Income/Age; CoveredByInsurance uses SourceClaimStatus + procedure sensitivity/high-cost + claim type + doctor pattern. | AD38: =IF(OR(C38="Có",C38="Yes"),"yes",IF(OR(C38="Không",C38="No"),"no","unknown")) | AE38: =IF(OR(F38="Có",F38="Yes"),"covered",IF(OR(F38="Không",F38="No"),"out_of_insurance","unknown")) | AF38: =IF(AND(AD38="yes",AE38="out_of_insurance"),"REVIEW","")
A39: 6aea7e62-b7d1-44c1-b750-ec46f3711a07 | B39: BN-00038 / Patient 7183469E | C39: Có | D39: BS. Huỳnh Mai | E39: Nhi / Pediatrics | F39: Không | G39: 6701960 | H39: Glucose máu / Blood glucose | J39: Thiếu ICD/context rõ / Missing clear ICD/context | K39: 91 | L39: M | M39: 72461.32 | N39: Married | O39: Retired | P39: 45474 | Q39: Outpatient | R39: Online | S39: Woodberg | T39: Denied | U39: Legitimate | V39: 3 | W39: 7183469e-9b60-4c10-86c4-81bdf75d5701 | X39: d2fa1e72-938b-4efe-8574-81ed8488f727 | Y39: tZ954 | Z39: OW435 | AA39: 0.79 | AB39: 0.02 | AC39: Derived from original claim row: HasInsurance uses PatientEmploymentStatus/ClaimType/SubmissionMethod/Income/Age; CoveredByInsurance uses SourceClaimStatus + procedure sensitivity/high-cost + claim type + doctor pattern. | AD39: =IF(OR(C39="Có",C39="Yes"),"yes",IF(OR(C39="Không",C39="No"),"no","unknown")) | AE39: =IF(OR(F39="Có",F39="Yes"),"covered",IF(OR(F39="Không",F39="No"),"out_of_insurance","unknown")) | AF39: =IF(AND(AD39="yes",AE39="out_of_insurance"),"REVIEW","")
A40: 70946881-265b-46c4-a3d8-635bf1bc5aad | B40: BN-00039 / Patient 6316D010 | C40: Không | D40: BS. Huỳnh Mai | E40: Nhi / Pediatrics | F40: Chưa rõ | G40: 8292630 | H40: CRP định lượng / CRP | I40: J18.9 | J40: Nghi viêm phổi / Suspected pneumonia | K40: 71 | L40: F | M40: 62160.78 | N40: Widowed | O40: Retired | P40: 45474 | Q40: Emergency | R40: Online | S40: South Sherrifort | T40: Denied | U40: Legitimate | V40: 3 | W40: 6316d010-b2b9-4d60-b6f1-f850e74091ae | X40: 2a244dc6-b87e-4c88-bdff-3a32565a682b | Y40: Hw668 | Z40: bo251 | AA40: 0.86 | AB40: 0.05 | AC40: Derived from original claim row: HasInsurance uses PatientEmploymentStatus/ClaimType/SubmissionMethod/Income/Age; CoveredByInsurance uses SourceClaimStatus + procedure sensitivity/high-cost + claim type + doctor pattern. | AD40: =IF(OR(C40="Có",C40="Yes"),"yes",IF(OR(C40="Không",C40="No"),"no","unknown")) | AE40: =IF(OR(F40="Có",F40="Yes"),"covered",IF(OR(F40="Không",F40="No"),"out_of_insurance","unknown")) | AF40: =IF(AND(AD40="yes",AE40="out_of_insurance"),"REVIEW","")
A41: 108c8e18-a9b0-4a3f-be62-09441a81074d | B41: BN-00040 / Patient 9C1DA429 | C41: Không | D41: BS. Nguyễn Minh | E41: Tim mạch / Cardiology | F41: Chưa rõ | G41: 7778560 | H41: Siêu âm tim / Echocardiography | I41: I50.9 | J41: Suy tim / Heart failure | K41: 88 | L41: M | M41: 39028.5 | N41: Single | O41: Student | P41: 45474 | Q41: Outpatient | R41: Paper | S41: Lake Amandabury | T41: Approved | U41: Fraud | V41: 1 | W41: 9c1da429-2788-4f9e-bc1e-af39ac11e860 | X41: fcc6ba88-6aa3-4e17-aa20-fcd4dd559c97 | Y41: LQ131 | Z41: gY651 | AA41: 0.67 | AB41: 0.05 | AC41: Derived from original claim row: HasInsurance uses PatientEmploymentStatus/ClaimType/SubmissionMethod/Income/Age; CoveredByInsurance uses SourceClaimStatus + procedure sensitivity/high-cost + claim type + doctor pattern. | AD41: =IF(OR(C41="Có",C41="Yes"),"yes",IF(OR(C41="Không",C41="No"),"no","unknown")) | AE41: =IF(OR(F41="Có",F41="Yes"),"covered",IF(OR(F41="Không",F41="No"),"out_of_insurance","unknown")) | AF41: =IF(AND(AD41="yes",AE41="out_of_insurance"),"REVIEW","")
A42: 7437d7b6-a6cf-43de-b52d-c87835612fb7 | B42: BN-00041 / Patient 31EC8DFE | C42: Không | D42: BS. Nguyễn Minh | E42: Tim mạch / Cardiology | F42: Không | G42: 2541380 | H42: Đông máu PT/aPTT / Coagulation test | I42: I24.9 | J42: Bệnh tim thiếu máu cục bộ cấp / Acute ischemic heart disease | K42: 66 | L42: M | M42: 48765.96 | N42: Divorced | O42: Unemployed | P42: 45474 | Q42: Outpatient | R42: Phone | S42: Susanton | T42: Approved | U42: Legitimate | V42: 1 | W42: 31ec8dfe-92e0-4a27-b6ad-ee17b2b09b15 | X42: 9dc8e27b-484e-45af-8ba8-d08dbe0b3464 | Y42: eK101 | Z42: hU802 | AA42: 0.63 | AB42: 0.05 | AC42: Derived from original claim row: HasInsurance uses PatientEmploymentStatus/ClaimType/SubmissionMethod/Income/Age; CoveredByInsurance uses SourceClaimStatus + procedure sensitivity/high-cost + claim type + doctor pattern. | AD42: =IF(OR(C42="Có",C42="Yes"),"yes",IF(OR(C42="Không",C42="No"),"no","unknown")) | AE42: =IF(OR(F42="Có",F42="Yes"),"covered",IF(OR(F42="Không",F42="No"),"out_of_insurance","unknown")) | AF42: =IF(AND(AD42="yes",AE42="out_of_insurance"),"REVIEW","")
A43: 067b75ca-0237-470b-acf9-975a8a037893 | B43: BN-00042 / Patient 8508346E | C43: Không | D43: BS. Huỳnh Mai | E43: Nhi / Pediatrics | F43: Chưa rõ | G43: 3777530 | H43: HbA1c | I43: E11.9 | J43: Đái tháo đường type 2 / Type 2 diabetes mellitus | K43: 60 | L43: F | M43: 45753.55 | N43: Single | O43: Employed | P43: 45474 | Q43: Routine | R43: Paper | S43: Lake Angela | T43: Approved | U43: Legitimate | V43: 1 | W43: 8508346e-a09f-4e90-bd5b-d1fbdd3a96c5 | X43: be79ec32-7c93-4a71-a691-b4b09ec86890 | Y43: gj573 | Z43: hI064 | AA43: 0.8 | AB43: 0.05 | AC43: Derived from original claim row: HasInsurance uses PatientEmploymentStatus/ClaimType/SubmissionMethod/Income/Age; CoveredByInsurance uses SourceClaimStatus + procedure sensitivity/high-cost + claim type + doctor pattern. | AD43: =IF(OR(C43="Có",C43="Yes"),"yes",IF(OR(C43="Không",C43="No"),"no","unknown")) | AE43: =IF(OR(F43="Có",F43="Yes"),"covered",IF(OR(F43="Không",F43="No"),"out_of_insurance","unknown")) | AF43: =IF(AND(AD43="yes",AE43="out_of_insurance"),"REVIEW","")
A44: f8f53415-e6a5-4eca-93e0-cb6e9e8e5e7e | B44: BN-00043 / Patient 9ED425F3 | C44: Có | D44: BS. Phạm Khoa | E44: Thần kinh / Neurology | F44: Có | G44: 7250300 | H44: CT đánh giá đột quỵ / Stroke CT | I44: I63.9 | J44: Nhồi máu não / Cerebral infarction | K44: 2 | L44: F | M44: 57424.34 | N44: Married | O44: Unemployed | P44: 45473 | Q44: Inpatient | R44: Paper | S44: Johnsonstad | T44: Approved | U44: Legitimate | V44: 3 | W44: 9ed425f3-1e36-45a9-8c54-e3dc04b28889 | X44: 8d2293b4-1326-48c0-bfe3-41819aa2d169 | Y44: qJ657 | Z44: OE737 | AA44: 0.65 | AB44: 0.41 | AC44: Derived from original claim row: HasInsurance uses PatientEmploymentStatus/ClaimType/SubmissionMethod/Income/Age; CoveredByInsurance uses SourceClaimStatus + procedure sensitivity/high-cost + claim type + doctor pattern. | AD44: =IF(OR(C44="Có",C44="Yes"),"yes",IF(OR(C44="Không",C44="No"),"no","unknown")) | AE44: =IF(OR(F44="Có",F44="Yes"),"covered",IF(OR(F44="Không",F44="No"),"out_of_insurance","unknown")) | AF44: =IF(AND(AD44="yes",AE44="out_of_insurance"),"REVIEW","")
A45: c1133fe9-3334-4f4e-9404-f0bede393625 | B45: BN-00044 / Patient B787A5F5 | C45: Có | D45: BS. Trương Khải | E45: Tim mạch / Cardiology | F45: Không | G45: 2729440 | H45: CRP định lượng / CRP | I45: R79.8 | J45: Bất thường xét nghiệm máu / Abnormal blood chemistry | K45: 8 | L45: F | M45: 20392.71 | N45: Widowed | O45: Unemployed | P45: 45473 | Q45: Outpatient | R45: Online | S45: Justinview | T45: Approved | U45: Legitimate | V45: 1 | W45: b787a5f5-0501-4099-9183-3d1454aa61ce | X45: ee09c03c-211f-4dae-8299-ab4e7b20d531 | Y45: Py657 | Z45: ss635 | AA45: 0.66 | AB45: 0.7 | AC45: Derived from original claim row: HasInsurance uses PatientEmploymentStatus/ClaimType/SubmissionMethod/Income/Age; CoveredByInsurance uses SourceClaimStatus + procedure sensitivity/high-cost + claim type + doctor pattern. | AD45: =IF(OR(C45="Có",C45="Yes"),"yes",IF(OR(C45="Không",C45="No"),"no","unknown")) | AE45: =IF(OR(F45="Có",F45="Yes"),"covered",IF(OR(F45="Không",F45="No"),"out_of_insurance","unknown")) | AF45: =IF(AND(AD45="yes",AE45="out_of_insurance"),"REVIEW","")
A46: 82e8345f-de91-4c65-affc-b4e836c854f1 | B46: BN-00045 / Patient 13362676 | C46: Có | D46: BS. Cao Vy | E46: Khám tổng quát / General Practice | F46: Có | G46: 2671560 | H46: HIV Ag/Ab combo | I46: Z11.4 | J46: Sàng lọc HIV / HIV screening | K46: 40 | L46: M | M46: 37554.96 | N46: Married | O46: Unemployed | P46: 45473 | Q46: Outpatient | R46: Paper | S46: Christopherbury | T46: Approved | U46: Legitimate | V46: 1 | W46: 13362676-eda2-4309-860d-39291a526f28 | X46: 27c1f238-343b-46de-ac7f-6601030beaa3 | Y46: ka847 | Z46: ws019 | AA46: 0.62 | AB46: 0.7 | AC46: Derived from original claim row: HasInsurance uses PatientEmploymentStatus/ClaimType/SubmissionMethod/Income/Age; CoveredByInsurance uses SourceClaimStatus + procedure sensitivity/high-cost + claim type + doctor pattern. | AD46: =IF(OR(C46="Có",C46="Yes"),"yes",IF(OR(C46="Không",C46="No"),"no","unknown")) | AE46: =IF(OR(F46="Có",F46="Yes"),"covered",IF(OR(F46="Không",F46="No"),"out_of_insurance","unknown")) | AF46: =IF(AND(AD46="yes",AE46="out_of_insurance"),"REVIEW","")
A47: 35680a70-b21d-4ec5-84df-3f5906697eff | B47: BN-00046 / Patient 134681A6 | C47: Không | D47: BS. Nguyễn Nhi | E47: Nhi / Pediatrics | F47: Không | G47: 5022030 | H47: CRP định lượng / CRP | I47: J18.9 | J47: Nghi viêm phổi / Suspected pneumonia | K47: 54 | L47: F | M47: 129946.83 | N47: Single | O47: Employed | P47: 45473 | Q47: Emergency | R47: Phone | S47: Michaelberg | T47: Approved | U47: Legitimate | V47: 2 | W47: 134681a6-c412-41d8-bcd1-00e2a1fb233e | X47: a4c9ca9c-3067-4f6d-9715-48f9cdb1ca1d | Y47: wz789 | Z47: ir511 | AA47: 0.79 | AB47: 0.05 | AC47: Derived from original claim row: HasInsurance uses PatientEmploymentStatus/ClaimType/SubmissionMethod/Income/Age; CoveredByInsurance uses SourceClaimStatus + procedure sensitivity/high-cost + claim type + doctor pattern. | AD47: =IF(OR(C47="Có",C47="Yes"),"yes",IF(OR(C47="Không",C47="No"),"no","unknown")) | AE47: =IF(OR(F47="Có",F47="Yes"),"covered",IF(OR(F47="Không",F47="No"),"out_of_insurance","unknown")) | AF47: =IF(AND(AD47="yes",AE47="out_of_insurance"),"REVIEW","")
A48: 0d09dc24-98e9-4999-987f-8058197c8c23 | B48: BN-00047 / Patient A19C3CDC | C48: Có | D48: BS. Phan Gia | E48: Tim mạch / Cardiology | F48: Có | G48: 747120 | H48: Men tim CK-MB / Cardiac enzyme CK-MB | I48: I20.9 | J48: Đau thắt ngực / Angina | K48: 24 | L48: F | M48: 121502.11 | N48: Married | O48: Employed | P48: 45473 | Q48: Routine | R48: Phone | S48: East Joshua | T48: Pending | U48: Legitimate | V48: 2 | W48: a19c3cdc-590b-46e4-89bd-773b0cb27073 | X48: a80cf751-211e-4202-91bf-19ce56b8a9d6 | Y48: qt767 | Z48: Wg679 | AA48: 0.66 | AB48: 0.2 | AC48: Derived from original claim row: HasInsurance uses PatientEmploymentStatus/ClaimType/SubmissionMethod/Income/Age; CoveredByInsurance uses SourceClaimStatus + procedure sensitivity/high-cost + claim type + doctor pattern. | AD48: =IF(OR(C48="Có",C48="Yes"),"yes",IF(OR(C48="Không",C48="No"),"no","unknown")) | AE48: =IF(OR(F48="Có",F48="Yes"),"covered",IF(OR(F48="Không",F48="No"),"out_of_insurance","unknown")) | AF48: =IF(AND(AD48="yes",AE48="out_of_insurance"),"REVIEW","")
A49: 0d953c29-0160-48f0-9c92-c6d7864d46cd | B49: BN-00048 / Patient 78F02CF7 | C49: Không | D49: BS. Phan Gia | E49: Tim mạch / Cardiology | F49: Chưa rõ | G49: 7551890 | H49: Men tim CK-MB / Cardiac enzyme CK-MB | I49: I20.9 | J49: Đau thắt ngực / Angina | K49: 21 | L49: M | M49: 140028.94 | N49: Divorced | O49: Employed | P49: 45472 | Q49: Outpatient | R49: Paper | S49: Lake Dale | T49: Pending | U49: Legitimate | V49: 2 | W49: 78f02cf7-53e5-4116-9ff4-24ac86325605 | X49: 7da0b046-5984-4417-8276-b98625789332 | Y49: mS696 | Z49: yX560 | AA49: 0.66 | AB49: 0.05 | AC49: Derived from original claim row: HasInsurance uses PatientEmploymentStatus/ClaimType/SubmissionMethod/Income/Age; CoveredByInsurance uses SourceClaimStatus + procedure sensitivity/high-cost + claim type + doctor pattern. | AD49: =IF(OR(C49="Có",C49="Yes"),"yes",IF(OR(C49="Không",C49="No"),"no","unknown")) | AE49: =IF(OR(F49="Có",F49="Yes"),"covered",IF(OR(F49="Không",F49="No"),"out_of_insurance","unknown")) | AF49: =IF(AND(AD49="yes",AE49="out_of_insurance"),"REVIEW","")
A50: 1749a49c-f588-41e6-9522-69ddb3567717 | B50: BN-00049 / Patient DD339506 | C50: Có | D50: BS. Trịnh Long | E50: Khám tổng quát / General Practice | F50: Có | G50: 7921300 | H50: HIV test nhanh / Rapid HIV test | I50: Z11.4 | J50: Sàng lọc HIV / HIV screening | K50: 94 | L50: F | M50: 33968.92 | N50: Divorced | O50: Student | P50: 45472 | Q50: Inpatient | R50: Paper | S50: Kellymouth | T50: Approved | U50: Fraud | V50: 1 | W50: dd339506-2019-4c75-89e9-efdc3e6227fc | X50: 71bc6532-8cee-4673-90aa-f694b99dbfc4 | Y50: DS530 | Z50: zx752 | AA50: 0.74 | AB50: 0.51 | AC50: Derived from original claim row: HasInsurance uses PatientEmploymentStatus/ClaimType/SubmissionMethod/Income/Age; CoveredByInsurance uses SourceClaimStatus + procedure sensitivity/high-cost + claim type + doctor pattern. | AD50: =IF(OR(C50="Có",C50="Yes"),"yes",IF(OR(C50="Không",C50="No"),"no","unknown")) | AE50: =IF(OR(F50="Có",F50="Yes"),"covered",IF(OR(F50="Không",F50="No"),"out_of_insurance","unknown")) | AF50: =IF(AND(AD50="yes",AE50="out_of_insurance"),"REVIEW","")
A51: f9e9f653-3252-4e0e-b11a-14aa00d34f62 | B51: BN-00050 / Patient B2835438 | C51: Không | D51: BS. Lưu Quang | E51: Thần kinh / Neurology | F51: Không | G51: 3042650 | H51: Khám chuyên khoa thần kinh / Neurology consultation | I51: R51 | J51: Đau đầu / Headache | K51: 12 | L51: F | M51: 86327.68 | N51: Divorced | O51: Unemployed | P51: 45472 | Q51: Inpatient | R51: Paper | S51: South Stacyville | T51: Approved | U51: Legitimate | V51: 0 | W51: b2835438-cbc7-4c0e-826b-fec852375524 | X51: a15f6652-dc3d-4c2c-88ea-56a3bdb83007 | Y51: Cg426 | Z51: PU908 | AA51: 0.65 | AB51: 0.05 | AC51: Derived from original claim row: HasInsurance uses PatientEmploymentStatus/ClaimType/SubmissionMethod/Income/Age; CoveredByInsurance uses SourceClaimStatus + procedure sensitivity/high-cost + claim type + doctor pattern. | AD51: =IF(OR(C51="Có",C51="Yes"),"yes",IF(OR(C51="Không",C51="No"),"no","unknown")) | AE51: =IF(OR(F51="Có",F51="Yes"),"covered",IF(OR(F51="Không",F51="No"),"out_of_insurance","unknown")) | AF51: =IF(AND(AD51="yes",AE51="out_of_insurance"),"REVIEW","")
... A59: e790e43a-d945-4ea6-b10a-1734513d86ca | B59: BN-00058 / Patient B807474C | C59: Không | D59: BS. Trần An | E59: Chấn thương chỉnh hình / Orthopedics | F59: Không | G59: 9811780 | H59: Đo mật độ xương / Bone density scan | I59: M81.0 | J59: Loãng xương / Osteoporosis | K59: 6 | L59: M | M59: 67795.55 | N59: Single | O59: Employed | P59: 45471 | Q59: Outpatient | R59: Online | S59: Andrefurt | T59: Denied | U59: Legitimate | V59: 3 | W59: b807474c-00dc-46a1-94c1-cd1bbd0cb032 | X59: b0768e9e-21bf-401a-8194-b8f1195957fe | Y59: hM349 | Z59: DK622 | AA59: 0.74 | AB59: 0.05 | AC59: Derived from original claim row: HasInsurance uses PatientEmploymentStatus/ClaimType/SubmissionMethod/Income/Age; CoveredByInsurance uses SourceClaimStatus + procedure sensitivity/high-cost + claim type + doctor pattern. | AD59: =IF(OR(C59="Có",C59="Yes"),"yes",IF(OR(C59="Không",C59="No"),"no","unknown")) | AE59: =IF(OR(F59="Có",F59="Yes"),"covered",IF(OR(F59="Không",F59="No"),"out_of_insurance","unknown")) | AF59: =IF(AND(AD59="yes",AE59="out_of_insurance"),"REVIEW","")
A60: 92a950cd-e460-4331-ad2a-377013c73eaf | B60: BN-00059 / Patient 119EBA64 | C60: Có | D60: BS. Trương Khải | E60: Tim mạch / Cardiology | F60: Không | G60: 8965680 | H60: Đông máu PT/aPTT / Coagulation test | J60: Thiếu ICD/context rõ / Missing clear ICD/context | K60: 64 | L60: F | M60: 69143.24 | N60: Widowed | O60: Employed | P60: 45470 | Q60: Routine | R60: Paper | S60: Craneborough | T60: Denied | U60: Legitimate | V60: 3 | W60: 119eba64-b7da-49e2-af92-2d0330e7dec4 | X60: 05188274-e51e-4642-b143-4df1bfa9bdac | Y60: SS572 | Z60: RX861 | AA60: 0.7 | AB60: 0.02 | AC60: Derived from original claim row: HasInsurance uses PatientEmploymentStatus/ClaimType/SubmissionMethod/Income/Age; CoveredByInsurance uses SourceClaimStatus + procedure sensitivity/high-cost + claim type + doctor pattern. | AD60: =IF(OR(C60="Có",C60="Yes"),"yes",IF(OR(C60="Không",C60="No"),"no","unknown")) | AE60: =IF(OR(F60="Có",F60="Yes"),"covered",IF(OR(F60="Không",F60="No"),"out_of_insurance","unknown")) | AF60: =IF(AND(AD60="yes",AE60="out_of_insurance"),"REVIEW","")
...

Sheet README
A1: Over-Ordering Sentinel MVP - Large source-based sample
A3: Mục đích / Purpose
A4: File này mở rộng từ file overordering mẫu cũ và dùng toàn bộ logic nguồn của file Health Insurance Fraud Claims để tạo dataset lớn hơn.
A5: Sheet cần chọn trong app / Sheet to select in app | B5: Data
A7: Luồng nghiệp vụ / Business logic
A8: App phải lọc HasInsurance = Có trước, sau đó trong nhóm đó mới thống kê CoveredByInsurance = Không.
A9: HasInsurance = bệnh nhân có bảo hiểm hay không. CoveredByInsurance = từng chỉ định có được bảo hiểm chi trả hay không.
A11: Nguồn dữ liệu / Data origin
A12: 4500 dòng được lấy/adapt từ file gốc Health Insurance Fraud Claims: ClaimID, PatientID, ProviderID, ClaimAmount, ClaimDate, DiagnosisCode, ProcedureCode, PatientAge, PatientGender, ProviderSpecialty, ClaimStatus, PatientIncome, PatientMaritalStatus, PatientEmploymentStatus, ProviderLocation, ClaimType, ClaimSubmissionMethod, Cluster, ClaimLegitimacy.
A13: Các cột chuẩn của app được suy luận có kiểm soát từ dữ liệu gốc: HasInsurance từ hồ sơ bệnh nhân; CoveredByInsurance từ trạng thái claim + loại dịch vụ + nhạy cảm/chi phí cao + mẫu bác sĩ.
A15: Lưu ý an toàn / Safety note
A16: Đây là dataset demo để kiểm thử logic phân tích, không dùng để kết luận sai phạm thật.

Sheet Data_Dictionary
A1: Column | B1: Required | C1: Meaning | D1: Derivation / Source
A2: Mã hồ sơ / ClaimID | B2: Recommended | C2: Mã hồ sơ/chỉ định. | D2: Giữ từ ClaimID nguồn.
A3: Tên bệnh nhân / PatientName | B3: Required | C3: Định danh bệnh nhân trong demo. | D3: Tạo từ PatientID nguồn + số dòng để dễ đọc.
A4: Có bảo hiểm / HasInsurance | B4: Required | C4: Bệnh nhân có bảo hiểm hay không. | D4: Suy luận từ EmploymentStatus, ClaimType, ClaimSubmissionMethod, Income, Age, ClaimStatus. Không lấy trực tiếp từ CoveredByInsurance.
A5: Tên bác sĩ / DoctorName | B5: Required | C5: Bác sĩ/người chỉ định. | D5: Tạo bút danh từ ProviderSpecialty + ProviderID để có bác sĩ lặp lại và có thể group.
A6: Khoa / Department | B6: Recommended | C6: Khoa/chuyên khoa. | D6: Dịch từ ProviderSpecialty nguồn.
A7: Trong bảo hiểm / CoveredByInsurance | B7: Required | C7: Từng chỉ định có được bảo hiểm chi trả hay không. | D7: Suy luận từ SourceClaimStatus + procedure sensitivity/high-cost + ClaimType + doctor pattern.
A8: Số tiền yêu cầu thanh toán VND / ClaimAmountVND | B8: Recommended | C8: Chi phí yêu cầu thanh toán. | D8: ClaimAmount nguồn × 1000, có ngưỡng tối thiểu cho dịch vụ nhạy cảm/chi phí cao.
A9: Tên dịch vụ / ProcedureName | B9: Recommended | C9: Tên xét nghiệm/thủ thuật/dịch vụ. | D9: Tạo từ ProviderSpecialty + ProcedureCode + ClaimStatus/ClaimType.
A10: Mã ICD10 / DiagnosisCode | B10: Recommended | C10: ICD/context chính. | D10: Tạo ICD hợp lý theo dịch vụ; một số case ngoài BH cố ý thiếu ICD để test Tool 04.
A11: Chẩn đoán / DiagnosisName | B11: Recommended | C11: Tên chẩn đoán/context. | D11: Tạo theo dịch vụ và ICD.
A12: Formula has_insurance_status | B12: Optional | C12: Công thức Excel mô phỏng normalize HasInsurance. | D12: Công thức trên cột C.
... A14: Formula review_flag | B14: Optional | C14: Flag BN có BH + ngoài BH. | D14: IF has_insurance_status=yes AND covered_status=out_of_insurance.

Sheet Derivation_Rules
A1: Rule block | B1: Logic used | C1: Why this makes data more realistic
A2: HasInsurance inference | B2: Probability score uses PatientEmploymentStatus, ClaimType, ClaimSubmissionMethod, PatientIncome, PatientAge, SourceClaimStatus. | C2: Insurance status belongs to patient, not to a single procedure. It is not copied from CoveredByInsurance.
A3: CoveredByInsurance inference | B3: Approved claims tend toward Có; Denied claims tend toward Không; Pending tends toward Chưa rõ/Không. Adjusted by high-cost/sensitive procedures, emergency/inpatient context, doctor pattern. | C3: Coverage status belongs to each order/procedure and may vary across rows.
A4: Doctor grouping | B4: ProviderID is converted into repeated pseudonymous doctors inside each ProviderSpecialty. | C4: Creates meaningful by-doctor aggregation instead of thousands of one-row providers.
A5: Procedure generation | B5: ProviderSpecialty + ProcedureCode + ClaimStatus + ClaimType select realistic procedure pools: MRI, CT, HIV, Glucose, HbA1c, Troponin, CRP, Coagulation, etc. | C5: Supports Tool 03 high-cost/sensitive review and Tool 04 ICD/context checks.
A6: ICD/context signal | B6: Most rows receive plausible ICD. Some insured + out-of-insurance + sensitive rows intentionally have blank ICD/context. | C6: Creates a test set for Required ICD Flags without claiming real clinical truth.
A7: Formula columns | B7: Columns AD-AF contain Excel formulas for normalized status and review flag. | C7: Allows manual verification of app logic inside Excel.

Sheet Expected_Check
A1: Metric | B1: Excel formula | C1: Static expected value | D1: Purpose
A2: Total rows | B2: =ROWS(Data!A2:A4501) | C2: 4500 | D2: Tổng số dòng chỉ định.
A3: Total patients | B3: =COUNTA(UNIQUE(Data!B2:B4501)) | C3: 4500 | D3: Số bệnh nhân trong file.
A4: Insured patients | B4: =COUNTA(UNIQUE(FILTER(Data!B2:B4501,Data!C2:C4501="Có"))) | C4: 3002 | D4: Bệnh nhân có bảo hiểm.
A5: Orders for insured | B5: =COUNTIF(Data!C2:C4501,"Có") | C5: 3002 | D5: Dòng chỉ định của BN có BH.
A6: Covered orders in insured | B6: =COUNTIFS(Data!C2:C4501,"Có",Data!F2:F4501,"Có") | C6: 918 | D6: Chỉ định được bảo hiểm chi trả.
A7: Out-of-insurance orders in insured | B7: =COUNTIFS(Data!C2:C4501,"Có",Data!F2:F4501,"Không") | C7: 1547 | D7: Chỉ định ngoài bảo hiểm trong nhóm BN có BH.
A8: Unknown coverage in insured | B8: =COUNTIFS(Data!C2:C4501,"Có",Data!F2:F4501,"Chưa rõ") | C8: 537 | D8: Trạng thái chi trả chưa rõ trong nhóm BN có BH.
A9: Out-of-insurance amount VND | B9: =SUMIFS(Data!G2:G4501,Data!C2:C4501,"Có",Data!F2:F4501,"Không") | C9: 7886905920 | D9: Chi phí ngoài BH trong nhóm BN có BH.
A10: Review flags | B10: =COUNTIF(Data!AF2:AF4501,"REVIEW") | C10: 1547 | D10: Flag formula trong Data.

Sheet Source_Profile
A1: Original field | B1: Value | C1: Count
A2: ProviderSpecialty | B2: Nhi / Pediatrics | C2: 955
A3: ProviderSpecialty | B3: Tim mạch / Cardiology | C3: 907
A4: ProviderSpecialty | B4: Chấn thương chỉnh hình / Orthopedics | C4: 893
A5: ProviderSpecialty | B5: Khám tổng quát / General Practice | C5: 880
A6: ProviderSpecialty | B6: Thần kinh / Neurology | C6: 865
A7: ClaimStatus | B7: Approved | C7: 1522
A8: ClaimStatus | B8: Denied | C8: 1512
A9: ClaimStatus | B9: Pending | C9: 1466
A10: ClaimType | B10: Outpatient | C10: 1152
A11: ClaimType | B11: Routine | C11: 1149
A12: ClaimType | B12: Inpatient | C12: 1128
A13: ClaimType | B13: Emergency | C13: 1071
... A22: ClaimLegitimacy | B22: Fraud | C22: 270

Sheet Dashboard
A1: Over-Ordering Sentinel MVP - Large Source-Based Dataset
A3: Key metric | B3: Value
A4: Total rows | B4: 4500
A5: Insured patients | B5: 3002
A6: Orders for insured | B6: 3002
A7: Covered orders in insured | B7: 918
A8: Out-of-insurance orders in insured | B8: 1547
A9: Unknown coverage in insured | B9: 537
